2025-09-24 16:15:33,568 INFO: Microblog startup [in /Users/xavierrodriguez/projects/microblog/app/__init__.py:50]
2025-09-24 16:25:00,029 INFO: Microblog startup [in /Users/xavierrodriguez/projects/microblog/app/__init__.py:50]
2025-10-01 12:50:56,419 INFO: Microblog startup [in /Users/xavierrodriguez/projects/microblog/app/__init__.py:50]
2025-10-01 12:53:04,937 INFO: Microblog startup [in /Users/xavierrodriguez/projects/microblog/app/__init__.py:50]
2025-10-01 12:53:28,872 INFO: Microblog startup [in /Users/xavierrodriguez/projects/microblog/app/__init__.py:50]
2025-10-01 12:54:26,037 INFO: Microblog startup [in /Users/xavierrodriguez/projects/microblog/app/__init__.py:50]
2025-10-01 12:54:47,383 INFO: Microblog startup [in /Users/xavierrodriguez/projects/microblog/app/__init__.py:50]
2025-10-01 12:56:53,434 INFO: Microblog startup [in /Users/xavierrodriguez/projects/microblog/app/__init__.py:50]
2025-10-01 13:05:53,083 INFO: Microblog startup [in /Users/xavierrodriguez/projects/microblog/app/__init__.py:50]
2025-10-01 13:09:10,250 INFO: Microblog startup [in /Users/xavierrodriguez/projects/microblog/app/__init__.py:50]
2025-10-01 13:10:39,360 INFO: Microblog startup [in /Users/xavierrodriguez/projects/microblog/app/__init__.py:50]
2025-10-01 13:11:59,898 INFO: Microblog startup [in /Users/xavierrodriguez/projects/microblog/app/__init__.py:50]
2025-10-01 13:18:42,198 INFO: Microblog startup [in /Users/xavierrodriguez/projects/microblog/app/__init__.py:50]
2025-10-01 13:18:48,149 ERROR: Exception on /login [POST] [in /Users/xavierrodriguez/projects/microblog/.venv/lib/python3.13/site-packages/flask/app.py:875]
Traceback (most recent call last):
  File "/Users/xavierrodriguez/projects/microblog/.venv/lib/python3.13/site-packages/sqlalchemy/engine/base.py", line 1967, in _exec_single_context
    self.dialect.do_execute(
    ~~~~~~~~~~~~~~~~~~~~~~~^
        cursor, str_statement, effective_parameters, context
        ^^^^^^^^^^^^^^^^^^^^^^^^^^^^^^^^^^^^^^^^^^^^^^^^^^^^
    )
    ^
  File "/Users/xavierrodriguez/projects/microblog/.venv/lib/python3.13/site-packages/sqlalchemy/engine/default.py", line 951, in do_execute
    cursor.execute(statement, parameters)
    ~~~~~~~~~~~~~~^^^^^^^^^^^^^^^^^^^^^^^
sqlite3.OperationalError: no such table: user

The above exception was the direct cause of the following exception:

Traceback (most recent call last):
  File "/Users/xavierrodriguez/projects/microblog/.venv/lib/python3.13/site-packages/flask/app.py", line 1511, in wsgi_app
    response = self.full_dispatch_request()
  File "/Users/xavierrodriguez/projects/microblog/.venv/lib/python3.13/site-packages/flask/app.py", line 919, in full_dispatch_request
    rv = self.handle_user_exception(e)
  File "/Users/xavierrodriguez/projects/microblog/.venv/lib/python3.13/site-packages/flask/app.py", line 917, in full_dispatch_request
    rv = self.dispatch_request()
  File "/Users/xavierrodriguez/projects/microblog/.venv/lib/python3.13/site-packages/flask/app.py", line 902, in dispatch_request
    return self.ensure_sync(self.view_functions[rule.endpoint])(**view_args)  # type: ignore[no-any-return]
           ~~~~~~~~~~~~~~~~~~~~~~~~~~~~~~~~~~~~~~~~~~~~~~~~~~~~^^^^^^^^^^^^^
  File "/Users/xavierrodriguez/projects/microblog/app/routes.py", line 30, in login
    user = db.session.scalar(
        sa.select(User).where(User.username == form.username.data)
    )
  File "/Users/xavierrodriguez/projects/microblog/.venv/lib/python3.13/site-packages/sqlalchemy/orm/scoping.py", line 1840, in scalar
    return self._proxied.scalar(
           ~~~~~~~~~~~~~~~~~~~~^
        statement,
        ^^^^^^^^^^
    ...<3 lines>...
        **kw,
        ^^^^^
    )
    ^
  File "/Users/xavierrodriguez/projects/microblog/.venv/lib/python3.13/site-packages/sqlalchemy/orm/session.py", line 2413, in scalar
    return self._execute_internal(
           ~~~~~~~~~~~~~~~~~~~~~~^
        statement,
        ^^^^^^^^^^
    ...<4 lines>...
        **kw,
        ^^^^^
    )
    ^
  File "/Users/xavierrodriguez/projects/microblog/.venv/lib/python3.13/site-packages/sqlalchemy/orm/session.py", line 2251, in _execute_internal
    result: Result[Any] = compile_state_cls.orm_execute_statement(
                          ~~~~~~~~~~~~~~~~~~~~~~~~~~~~~~~~~~~~~~~^
        self,
        ^^^^^
    ...<4 lines>...
        conn,
        ^^^^^
    )
    ^
  File "/Users/xavierrodriguez/projects/microblog/.venv/lib/python3.13/site-packages/sqlalchemy/orm/context.py", line 306, in orm_execute_statement
    result = conn.execute(
        statement, params or {}, execution_options=execution_options
    )
  File "/Users/xavierrodriguez/projects/microblog/.venv/lib/python3.13/site-packages/sqlalchemy/engine/base.py", line 1419, in execute
    return meth(
        self,
        distilled_parameters,
        execution_options or NO_OPTIONS,
    )
  File "/Users/xavierrodriguez/projects/microblog/.venv/lib/python3.13/site-packages/sqlalchemy/sql/elements.py", line 526, in _execute_on_connection
    return connection._execute_clauseelement(
           ~~~~~~~~~~~~~~~~~~~~~~~~~~~~~~~~~^
        self, distilled_params, execution_options
        ^^^^^^^^^^^^^^^^^^^^^^^^^^^^^^^^^^^^^^^^^
    )
    ^
  File "/Users/xavierrodriguez/projects/microblog/.venv/lib/python3.13/site-packages/sqlalchemy/engine/base.py", line 1641, in _execute_clauseelement
    ret = self._execute_context(
        dialect,
    ...<8 lines>...
        cache_hit=cache_hit,
    )
  File "/Users/xavierrodriguez/projects/microblog/.venv/lib/python3.13/site-packages/sqlalchemy/engine/base.py", line 1846, in _execute_context
    return self._exec_single_context(
           ~~~~~~~~~~~~~~~~~~~~~~~~~^
        dialect, context, statement, parameters
        ^^^^^^^^^^^^^^^^^^^^^^^^^^^^^^^^^^^^^^^
    )
    ^
  File "/Users/xavierrodriguez/projects/microblog/.venv/lib/python3.13/site-packages/sqlalchemy/engine/base.py", line 1986, in _exec_single_context
    self._handle_dbapi_exception(
    ~~~~~~~~~~~~~~~~~~~~~~~~~~~~^
        e, str_statement, effective_parameters, cursor, context
        ^^^^^^^^^^^^^^^^^^^^^^^^^^^^^^^^^^^^^^^^^^^^^^^^^^^^^^^
    )
    ^
  File "/Users/xavierrodriguez/projects/microblog/.venv/lib/python3.13/site-packages/sqlalchemy/engine/base.py", line 2355, in _handle_dbapi_exception
    raise sqlalchemy_exception.with_traceback(exc_info[2]) from e
  File "/Users/xavierrodriguez/projects/microblog/.venv/lib/python3.13/site-packages/sqlalchemy/engine/base.py", line 1967, in _exec_single_context
    self.dialect.do_execute(
    ~~~~~~~~~~~~~~~~~~~~~~~^
        cursor, str_statement, effective_parameters, context
        ^^^^^^^^^^^^^^^^^^^^^^^^^^^^^^^^^^^^^^^^^^^^^^^^^^^^
    )
    ^
  File "/Users/xavierrodriguez/projects/microblog/.venv/lib/python3.13/site-packages/sqlalchemy/engine/default.py", line 951, in do_execute
    cursor.execute(statement, parameters)
    ~~~~~~~~~~~~~~^^^^^^^^^^^^^^^^^^^^^^^
sqlalchemy.exc.OperationalError: (sqlite3.OperationalError) no such table: user
[SQL: SELECT user.id, user.username, user.email, user.password_hash, user.about_me, user.last_seen 
FROM user 
WHERE user.username = ?]
[parameters: ('xavirod05',)]
(Background on this error at: https://sqlalche.me/e/20/e3q8)
2025-10-01 13:19:56,793 INFO: Microblog startup [in /Users/xavierrodriguez/projects/microblog/app/__init__.py:50]
2025-10-01 13:19:57,247 INFO: Microblog startup [in /Users/xavierrodriguez/projects/microblog/app/__init__.py:50]
2025-10-01 13:20:32,669 INFO: Microblog startup [in /Users/xavierrodriguez/projects/microblog/app/__init__.py:50]
2025-10-01 13:21:38,890 INFO: Microblog startup [in /Users/xavierrodriguez/projects/microblog/app/__init__.py:50]
2025-10-01 13:25:18,717 INFO: Microblog startup [in /Users/xavierrodriguez/projects/microblog/app/__init__.py:50]
2025-10-01 13:27:08,917 INFO: Microblog startup [in /Users/xavierrodriguez/projects/microblog/app/__init__.py:50]
2025-10-01 16:10:47,481 INFO: Microblog startup [in /Users/xavierrodriguez/projects/microblog/app/__init__.py:50]
2025-10-01 16:10:49,121 ERROR: Exception on / [GET] [in /Users/xavierrodriguez/projects/microblog/.venv/lib/python3.13/site-packages/flask/app.py:875]
Traceback (most recent call last):
  File "/Users/xavierrodriguez/projects/microblog/.venv/lib/python3.13/site-packages/flask/app.py", line 1511, in wsgi_app
    response = self.full_dispatch_request()
  File "/Users/xavierrodriguez/projects/microblog/.venv/lib/python3.13/site-packages/flask/app.py", line 919, in full_dispatch_request
    rv = self.handle_user_exception(e)
  File "/Users/xavierrodriguez/projects/microblog/.venv/lib/python3.13/site-packages/flask/app.py", line 917, in full_dispatch_request
    rv = self.dispatch_request()
  File "/Users/xavierrodriguez/projects/microblog/.venv/lib/python3.13/site-packages/flask/app.py", line 902, in dispatch_request
    return self.ensure_sync(self.view_functions[rule.endpoint])(**view_args)  # type: ignore[no-any-return]
           ~~~~~~~~~~~~~~~~~~~~~~~~~~~~~~~~~~~~~~~~~~~~~~~~~~~~^^^^^^^^^^^^^
  File "/Users/xavierrodriguez/projects/microblog/.venv/lib/python3.13/site-packages/flask_login/utils.py", line 290, in decorated_view
    return current_app.ensure_sync(func)(*args, **kwargs)
           ~~~~~~~~~~~~~~~~~~~~~~~~~~~~~^^^^^^^^^^^^^^^^^
  File "/Users/xavierrodriguez/projects/microblog/app/routes.py", line 26, in index
    page=page,
         ^^^^
UnboundLocalError: cannot access local variable 'page' where it is not associated with a value
2025-10-01 16:12:13,073 INFO: Microblog startup [in /Users/xavierrodriguez/projects/microblog/app/__init__.py:50]
2025-10-01 16:14:09,888 INFO: Microblog startup [in /Users/xavierrodriguez/projects/microblog/app/__init__.py:50]
2025-10-01 16:15:41,963 INFO: Microblog startup [in /Users/xavierrodriguez/projects/microblog/app/__init__.py:50]
2025-10-01 16:23:40,707 INFO: Microblog startup [in /Users/xavierrodriguez/projects/microblog/app/__init__.py:50]
2025-10-08 16:04:31,779 INFO: Microblog startup [in /Users/xavierrodriguez/projects/microblog/app/__init__.py:53]
2025-10-08 16:05:43,653 INFO: Microblog startup [in /Users/xavierrodriguez/projects/microblog/app/__init__.py:53]
